tomer@DESKTOP-9J2H91V:/mnt/c/Users/PC/Desktop/projects/python/my_project$ python3 my_flask.py
Traceback (most recent call last):
  File "/home/tomer/.local/lib/python3.10/site-packages/sqlalchemy/engine/base.py", line 1967, in _exec_single_context
    self.dialect.do_execute(
  File "/home/tomer/.local/lib/python3.10/site-packages/sqlalchemy/engine/default.py", line 941, in do_execute
    cursor.execute(statement, parameters)
psycopg2.errors.InsufficientPrivilege: permission denied for schema public
LINE 2: CREATE TABLE users (
                     ^


The above exception was the direct cause of the following exception:

Traceback (most recent call last):
  File "/mnt/c/Users/PC/Desktop/projects/python/my_project/my_flask.py", line 22, in <module>
    create_table()
  File "/mnt/c/Users/PC/Desktop/projects/python/my_project/database.py", line 51, in create_table
    Base.metadata.create_all(bind=engine)
  File "/home/tomer/.local/lib/python3.10/site-packages/sqlalchemy/sql/schema.py", line 5866, in create_all
    bind._run_ddl_visitor(
  File "/home/tomer/.local/lib/python3.10/site-packages/sqlalchemy/engine/base.py", line 3253, in _run_ddl_visitor
    conn._run_ddl_visitor(visitorcallable, element, **kwargs)
  File "/home/tomer/.local/lib/python3.10/site-packages/sqlalchemy/engine/base.py", line 2459, in _run_ddl_visitor
    visitorcallable(self.dialect, self, **kwargs).traverse_single(element)
  File "/home/tomer/.local/lib/python3.10/site-packages/sqlalchemy/sql/visitors.py", line 664, in traverse_single
    return meth(obj, **kw)
  File "/home/tomer/.local/lib/python3.10/site-packages/sqlalchemy/sql/ddl.py", line 918, in visit_metadata
    self.traverse_single(
  File "/home/tomer/.local/lib/python3.10/site-packages/sqlalchemy/sql/visitors.py", line 664, in traverse_single
    return meth(obj, **kw)
  File "/home/tomer/.local/lib/python3.10/site-packages/sqlalchemy/sql/ddl.py", line 956, in visit_table
    )._invoke_with(self.connection)
  File "/home/tomer/.local/lib/python3.10/site-packages/sqlalchemy/sql/ddl.py", line 314, in _invoke_with
    return bind.execute(self)
  File "/home/tomer/.local/lib/python3.10/site-packages/sqlalchemy/engine/base.py", line 1418, in execute
    return meth(
  File "/home/tomer/.local/lib/python3.10/site-packages/sqlalchemy/sql/ddl.py", line 180, in _execute_on_connection
    return connection._execute_ddl(
  File "/home/tomer/.local/lib/python3.10/site-packages/sqlalchemy/engine/base.py", line 1529, in _execute_ddl
    ret = self._execute_context(
  File "/home/tomer/.local/lib/python3.10/site-packages/sqlalchemy/engine/base.py", line 1846, in _execute_context
    return self._exec_single_context(
  File "/home/tomer/.local/lib/python3.10/site-packages/sqlalchemy/engine/base.py", line 1986, in _exec_single_context
    self._handle_dbapi_exception(
  File "/home/tomer/.local/lib/python3.10/site-packages/sqlalchemy/engine/base.py", line 2355, in _handle_dbapi_exception
    raise sqlalchemy_exception.with_traceback(exc_info[2]) from e
  File "/home/tomer/.local/lib/python3.10/site-packages/sqlalchemy/engine/base.py", line 1967, in _exec_single_context
    self.dialect.do_execute(
  File "/home/tomer/.local/lib/python3.10/site-packages/sqlalchemy/engine/default.py", line 941, in do_execute
    cursor.execute(statement, parameters)
sqlalchemy.exc.ProgrammingError: (psycopg2.errors.InsufficientPrivilege) permission denied for schema public
LINE 2: CREATE TABLE users (
                     ^

[SQL:
CREATE TABLE users (
        key SERIAL NOT NULL,
        id INTEGER,
        username VARCHAR(55),
        password VARCHAR,
        classification VARCHAR(1),
        age INTEGER,
        email VARCHAR(55),
        PRIMARY KEY (key)
)

]
(Background on this error at: https://sqlalche.me/e/20/f405)